#VRML_SIM R2023b utf8

EXTERNPROTO "https://raw.githubusercontent.com/cyberbotics/webots/R2023b/projects/objects/floors/protos/Floor.proto"
EXTERNPROTO "https://raw.githubusercontent.com/cyberbotics/webots/R2023b/projects/objects/backgrounds/protos/TexturedBackground.proto"
EXTERNPROTO "https://raw.githubusercontent.com/cyberbotics/webots/R2023b/projects/objects/backgrounds/protos/TexturedBackgroundLight.proto"

WorldInfo {
  basicTimeStep 64
}
Viewpoint {
  orientation -0.3446822615520155 0.019632321652779748 0.9385140971332876 3.131322111374631
  position 5.639157866981856 -0.7376985781516925 4.419759110407651
}
TexturedBackground {
}
TexturedBackgroundLight {
  luminosity 0.5
}
Floor {
  size 6 6
}
Robot {
  translation -2.47679 -2.5378 0.11
  rotation 0 0 1 1.5708
  children [
    DEF BODY Shape {
      appearance PBRAppearance {
        baseColor 0.917647 0.145098 0.145098
        roughness 1
        metalness 0
      }
      geometry Box {
        size 0.4 0.25 0.05
      }
    }
    DEF WHEEL1 HingeJoint {
      jointParameters HingeJointParameters {
        axis 0 1 0
        anchor 0.11 0.155 0
      }
      device [
        RotationalMotor {
          name "wheel_1"
        }
      ]
      endPoint Solid {
        translation 0.11 0.155 0
        rotation 1 6.783380654362097e-12 -6.7816143035901604e-12 1.5707999999999922
        children [
          DEF WHEEL Shape {
            appearance PBRAppearance {
              baseColor 0.305882 0.898039 0.25098
              roughness 1
              metalness 0
            }
            geometry Cylinder {
              height 0.05
              radius 0.1
              subdivision 24
            }
          }
        ]
        boundingObject USE WHEEL
        physics Physics {
        }
      }
    }
    DEF WHEEL2 HingeJoint {
      jointParameters HingeJointParameters {
        axis 0 1 0
        anchor 0.11 -0.155 0
      }
      device [
        RotationalMotor {
          name "wheel_2"
        }
      ]
      endPoint Solid {
        translation 0.11 -0.155 0
        rotation 1 6.782708459762788e-12 -6.783729017986574e-12 1.5707999999999884
        children [
          USE WHEEL
        ]
        name "solid(1)"
        boundingObject USE WHEEL
        physics Physics {
        }
      }
    }
    DEF WHEEL3 HingeJoint {
      jointParameters HingeJointParameters {
        axis 0 1 0
        anchor -0.11 0.155 0
      }
      device [
        RotationalMotor {
          name "wheel_3"
        }
      ]
      endPoint Solid {
        translation -0.11 0.155 0
        rotation 1 6.783390467421934e-12 -6.782394441847758e-12 1.5707999999999944
        children [
          USE WHEEL
        ]
        name "solid(2)"
        boundingObject USE WHEEL
        physics Physics {
        }
      }
    }
    DEF WHEEL4 HingeJoint {
      jointParameters HingeJointParameters {
        axis 0 1 0
        anchor -0.11 -0.155 0
      }
      device [
        RotationalMotor {
          name "wheel_4"
        }
      ]
      endPoint Solid {
        translation -0.11 -0.155 0
        rotation 1 6.785220603082877e-12 -6.782629955284033e-12 1.5707999999999893
        children [
          USE WHEEL
        ]
        name "solid(3)"
        boundingObject USE WHEEL
        physics Physics {
        }
      }
    }
    DEF DS_RIGHT DistanceSensor {
      translation 0.2 -0.0675 0
      rotation 0 0 1 -0.3
      children [
        Shape {
          appearance PBRAppearance {
            baseColor 0.184314 0.596078 0.847059
            roughness 1
            metalness 0
          }
          geometry Box {
            size 0.01 0.01 0.01
          }
        }
      ]
      name "ds_right"
    }
    DEF DS_LEFT DistanceSensor {
      translation 0.2 0.0675 0
      rotation 0 0 1 0.3
      children [
        Shape {
          appearance PBRAppearance {
            baseColor 0.184314 0.596078 0.847059
            roughness 1
            metalness 0
          }
          geometry Box {
            size 0.01 0.01 0.01
          }
        }
      ]
      name "ds_left"
    }
    DEF DS_CENTER DistanceSensor {
      translation 0.2 0 0
      children [
        Shape {
          appearance PBRAppearance {
            baseColor 0.184314 0.596078 0.847059
            roughness 1
            metalness 0
          }
          geometry Box {
            size 0.01 0.01 0.01
          }
        }
      ]
      name "ds_centre"
    }
    GPS {
    }
    Compass {
      rotation 0 0 1 -1.5707953071795862
    }
    DistanceSensor {
      translation 0 0.09 0.04
      rotation 0 0 1 -1.5707953071795862
      name "load_sensor_1"
      lookupTable [
        0 0 0
        0.2 1000 0
      ]
      numberOfRays 2
    }
    DistanceSensor {
      translation 0.05 -0.09 0.04
      rotation 0 0 1 1.5708
      name "load_sensor_2"
      lookupTable [
        0 0 0
        0.2 1000 0
      ]
      numberOfRays 2
    }
  ]
  name "mobile_robot"
  boundingObject USE BODY
  physics Physics {
    density -1
    mass 1
  }
  controller "mobile_robot_controller"
}
DEF RRR_robot Robot {
  translation -0.045 0.1 0.15
  rotation 0 0 1 3.14159
  children [
    Solid {
      children [
        DEF base_shape Shape {
          appearance DEF base_color_map PBRAppearance {
            baseColor 0.5 0.5 1
            roughness 1
            metalness 0
          }
          geometry Box {
            size 0.1 0.1 0.3
          }
        }
      ]
    }
    Solid {
      translation -0.1 -0.25 -0.1
      children [
        DEF dock Shape {
          appearance USE base_color_map
          geometry Box {
            size 0.3 0.4 0.1
          }
        }
      ]
      name "solid(2)"
      boundingObject USE dock
      physics Physics {
      }
    }
    DEF link_1_hinge_joint HingeJoint {
      jointParameters HingeJointParameters {
        anchor -0.1 0 0.1
      }
      device [
        PositionSensor {
          name "link_1_encoder"
        }
        RotationalMotor {
          name "link_1_motor"
        }
      ]
      endPoint Solid {
        translation -0.1 0 0.1
        rotation 0 1 0 -1.57
        children [
          Shape {
            appearance DEF hinge_color_map PBRAppearance {
              baseColor 0 1 1
              roughness 1
              metalness 0
            }
            geometry DEF hinge_shape Cylinder {
              height 0.1
              radius 0.03
            }
          }
          Pose {
            translation 0.1 0 0
            rotation 0 1 0 1.57
            children [
              Shape {
                appearance DEF link_color_map PBRAppearance {
                  baseColor 1 0.7 0.7
                  roughness 1
                  metalness 0
                }
                geometry Cylinder {
                  height 0.2
                  radius 0.02
                }
              }
            ]
          }
          DEF link_2_hinge_joint HingeJoint {
            jointParameters HingeJointParameters {
              axis 0 0 -1
              anchor 0.2 0 0
            }
            device [
              PositionSensor {
                name "link_2_encoder"
              }
              RotationalMotor {
                name "link_2_motor"
              }
            ]
            endPoint Solid {
              translation 0.2 0 0
              children [
                DEF hinge_2_shape Shape {
                  appearance USE hinge_color_map
                  geometry Cylinder {
                    height 0.1
                    radius 0.03
                  }
                }
                Pose {
                  translation 0.05 0 0
                  rotation 0 1 0 1.57
                  children [
                    Shape {
                      appearance USE link_color_map
                      geometry Cylinder {
                        height 0.1
                        radius 0.02
                      }
                    }
                  ]
                }
                DEF link_3_hinge_joint HingeJoint {
                  jointParameters HingeJointParameters {
                    axis 0 0 -1
                    anchor 0.1 0 0
                  }
                  device [
                    PositionSensor {
                      name "link_3_encoder"
                    }
                    RotationalMotor {
                      name "link_3_motor"
                    }
                  ]
                  endPoint Solid {
                    translation 0.1 0 0
                    children [
                      USE hinge_2_shape
                      Pose {
                        translation 0.075 0 0
                        rotation 0 1 0 1.57
                        children [
                          Shape {
                            appearance USE link_color_map
                            geometry Cylinder {
                              height 0.15
                              radius 0.02
                            }
                          }
                        ]
                      }
                      Connector {
                        translation 0.15 0 0
                        children [
                          DEF holder Shape {
                            appearance PBRAppearance {
                              baseColor 0 1 0
                              roughness 1
                              metalness 0
                            }
                            geometry Box {
                              size 0.01 0.1 0.2
                            }
                          }
                          DEF left_flank_pose Pose {
                            translation 0.055 0 -0.095
                            children [
                              DEF flank_shape Shape {
                                appearance DEF balck_color_map PBRAppearance {
                                  baseColor 0 0 0
                                  roughness 1
                                  metalness 0
                                }
                                geometry Box {
                                  size 0.1 0.1 0.01
                                }
                              }
                            ]
                          }
                          DEF right_flank_pose Pose {
                            translation 0.055 0 0.095
                            children [
                              USE flank_shape
                            ]
                          }
                        ]
                        model "load"
                        boundingObject USE holder
                        physics Physics {
                        }
                        distanceTolerance 0.2
                        axisTolerance 1
                        rotationTolerance 1
                      }
                    ]
                    boundingObject USE hinge_2_shape
                    physics Physics {
                    }
                  }
                }
              ]
              boundingObject USE hinge_2_shape
              physics Physics {
              }
            }
          }
        ]
        name "solid(1)"
        boundingObject USE hinge_shape
        physics Physics {
        }
      }
    }
    DistanceSensor {
      translation -0.16 -0.05 -0.05
      rotation 0 0 1 1.5708
      name "delivery_robot_sensor"
      lookupTable [
        0 0 0
        0.2 1000 0
      ]
    }
  ]
  boundingObject USE base_shape
  physics Physics {
  }
  controller "RRR_robot_controller"
}
DEF load Solid {
  translation 0.055 0.35 0.15
  rotation 0 1 0 -1.5707953071795862
  children [
    DEF box_shape Shape {
      appearance PBRAppearance {
        baseColor 1 1 0
        roughness 1
        metalness 0
      }
      geometry Box {
        size 0.08 0.08 0.08
      }
    }
    Connector {
      translation 0.06 0 0
      name "connector_load"
      model "load"
      distanceTolerance 0.2
      axisTolerance 1
      rotationTolerance 1
    }
  ]
  boundingObject USE box_shape
  physics Physics {
  }
}
