#VRML_SIM R2023b utf8

EXTERNPROTO "https://raw.githubusercontent.com/cyberbotics/webots/R2023b/projects/objects/floors/protos/Floor.proto"
EXTERNPROTO "https://raw.githubusercontent.com/cyberbotics/webots/R2023b/projects/objects/backgrounds/protos/TexturedBackground.proto"
EXTERNPROTO "https://raw.githubusercontent.com/cyberbotics/webots/R2023b/projects/objects/backgrounds/protos/TexturedBackgroundLight.proto"

WorldInfo {
  basicTimeStep 16
}
Viewpoint {
  orientation 0.1669328421654986 0.9233922548440731 -0.3456590370589597 0.689139408627051
  position -2.44093621250452 0.5772473188643316 2.2497735979999556
}
TexturedBackground {
}
TexturedBackgroundLight {
}
Floor {
  size 4 4
}
Robot {
  translation 0.3581647855657855 1.2940145713456628 0.03986048964813275
  rotation 4.253722737655616e-08 -3.709504998415499e-08 -0.9999999999999984 1.4343531908850502
  children [
    DEF BODY Shape {
      appearance PBRAppearance {
        baseColor 0.917647 0.145098 0.145098
        roughness 1
        metalness 0
      }
      geometry Box {
        size 0.2 0.1 0.05
      }
    }
    DEF WHEEL1 HingeJoint {
      jointParameters HingeJointParameters {
        position 266.97593039785585
        axis 0 1 0
        anchor 0.05 0.06 0
      }
      device [
        RotationalMotor {
          name "wheel1"
        }
      ]
      endPoint Solid {
        translation 0.05 0.06 0
        rotation 0.021018622373996647 0.7069492718474082 -0.7069518686218451 3.099561751983879
        children [
          DEF WHEEL Shape {
            appearance PBRAppearance {
              baseColor 0.305882 0.898039 0.25098
              roughness 1
              metalness 0
            }
            geometry Cylinder {
              height 0.02
              radius 0.04
              subdivision 24
            }
          }
        ]
        boundingObject USE WHEEL
        physics Physics {
        }
      }
    }
    DEF WHEEL2 HingeJoint {
      jointParameters HingeJointParameters {
        position 215.7760103846477
        axis 0 1 0
        anchor 0.05 -0.06 0
      }
      device [
        RotationalMotor {
          name "wheel2"
        }
      ]
      endPoint Solid {
        translation 0.05 -0.06 0
        rotation 0.35806461415004054 0.6602221330094512 -0.6602245581452064 2.453912610169318
        children [
          USE WHEEL
        ]
        name "solid(1)"
        boundingObject USE WHEEL
        physics Physics {
        }
      }
    }
    DEF WHEEL3 HingeJoint {
      jointParameters HingeJointParameters {
        position 266.975919522594
        axis 0 1 0
        anchor -0.05 0.06 0
      }
      device [
        RotationalMotor {
          name "wheel3"
        }
      ]
      endPoint Solid {
        translation -0.05 0.06 0
        rotation 0.021022468215762476 0.7069492146711711 -0.7069518114453994 3.099554063725734
        children [
          USE WHEEL
        ]
        name "solid(2)"
        boundingObject USE WHEEL
        physics Physics {
        }
      }
    }
    DEF WHEEL4 HingeJoint {
      jointParameters HingeJointParameters {
        position 215.77600418815285
        axis 0 1 0
        anchor -0.05 -0.06 0
      }
      device [
        RotationalMotor {
          name "wheel4"
        }
      ]
      endPoint Solid {
        translation -0.05 -0.06 0
        rotation 0.35806692194685147 0.6602215072046258 -0.6602239323380814 2.453908519108222
        children [
          USE WHEEL
        ]
        name "solid(3)"
        boundingObject USE WHEEL
        physics Physics {
        }
      }
    }
    DEF DS_RIGHT DistanceSensor {
      translation 0.1 -0.03 0
      rotation 0 0 1 -0.3
      children [
        Shape {
          appearance PBRAppearance {
            baseColor 0.184314 0.596078 0.847059
            roughness 1
            metalness 0
          }
          geometry Box {
            size 0.01 0.01 0.01
          }
        }
      ]
      name "ds_right"
    }
    DEF DS_LEFT DistanceSensor {
      translation 0.1 0.03 0
      rotation 0 0 1 0.3
      children [
        Shape {
          appearance PBRAppearance {
            baseColor 0.184314 0.596078 0.847059
            roughness 1
            metalness 0
          }
          geometry Box {
            size 0.01 0.01 0.01
          }
        }
      ]
      name "ds_left"
    }
  ]
  name "mobile_robot"
  boundingObject USE BODY
  physics Physics {
    density -1
    mass 1
  }
  controller "<none>"
  linearVelocity 0.005440805323790292 -0.039628242923708125 1.6619219589027848e-11
  angularVelocity 5.828256917230906e-09 -4.289800964989155e-08 -5.009011303287543e-08
}
DEF RRR_robot Robot {
  translation 0 0 0.15
  children [
    Solid {
      children [
        DEF base_shape Shape {
          appearance DEF base_color_map PBRAppearance {
            baseColor 0.5 0.5 1
            roughness 1
            metalness 0
          }
          geometry Box {
            size 0.1 0.1 0.3
          }
        }
      ]
    }
    DEF link_1_hinge_joint HingeJoint {
      jointParameters HingeJointParameters {
        anchor -0.1 0 0.1
      }
      device [
        PositionSensor {
          name "link_1_encoder"
        }
        RotationalMotor {
          name "link_1_motor"
        }
      ]
      endPoint Solid {
        translation -0.1 0 0.1
        rotation 0 1 0 -1.57
        children [
          Shape {
            appearance DEF hinge_color_map PBRAppearance {
              baseColor 0 1 1
              roughness 1
              metalness 0
            }
            geometry DEF hinge_shape Cylinder {
              height 0.1
              radius 0.03
            }
          }
          Pose {
            translation 0.1 0 0
            rotation 0 1 0 1.57
            children [
              Shape {
                appearance DEF link_color_map PBRAppearance {
                  baseColor 1 0.7 0.7
                  roughness 1
                  metalness 0
                }
                geometry Cylinder {
                  height 0.2
                  radius 0.02
                }
              }
            ]
          }
          DEF link_2_hinge_joint HingeJoint {
            jointParameters HingeJointParameters {
              axis 0 0 -1
              anchor 0.2 0 0
            }
            device [
              PositionSensor {
                name "link_2_encoder"
              }
              RotationalMotor {
                name "link_2_motor"
              }
            ]
            endPoint Solid {
              translation 0.2 0 0
              children [
                DEF hinge_2_shape Shape {
                  appearance USE hinge_color_map
                  geometry Cylinder {
                    height 0.1
                    radius 0.03
                  }
                }
                Pose {
                  translation 0.05 0 0
                  rotation 0 1 0 1.57
                  children [
                    Shape {
                      appearance USE link_color_map
                      geometry Cylinder {
                        height 0.1
                        radius 0.02
                      }
                    }
                  ]
                }
                DEF link_3_hinge_joint HingeJoint {
                  jointParameters HingeJointParameters {
                    axis 0 0 -1
                    anchor 0.1 0 0
                  }
                  device [
                    PositionSensor {
                      name "link_3_encoder"
                    }
                    RotationalMotor {
                      name "link_3_motor"
                    }
                  ]
                  endPoint Solid {
                    translation 0.1 0 0
                    children [
                      USE hinge_2_shape
                      Pose {
                        translation 0.075 0 0
                        rotation 0 1 0 1.57
                        children [
                          Shape {
                            appearance USE link_color_map
                            geometry Cylinder {
                              height 0.15
                              radius 0.02
                            }
                          }
                        ]
                      }
                      Connector {
                        translation 0.15 0 0
                        children [
                          DEF holder Shape {
                            appearance PBRAppearance {
                              baseColor 0 1 0
                              roughness 1
                              metalness 0
                            }
                            geometry Box {
                              size 0.01 0.1 0.2
                            }
                          }
                          DEF left_flank_pose Pose {
                            translation 0.055 0 -0.095
                            children [
                              DEF flank_shape Shape {
                                appearance DEF balck_color_map PBRAppearance {
                                  baseColor 0 0 0
                                  roughness 1
                                  metalness 0
                                }
                                geometry Box {
                                  size 0.1 0.1 0.01
                                }
                              }
                            ]
                          }
                          DEF right_flank_pose Pose {
                            translation 0.055 0 0.095
                            children [
                              USE flank_shape
                            ]
                          }
                        ]
                      }
                    ]
                    boundingObject USE hinge_2_shape
                    physics Physics {
                    }
                  }
                }
              ]
              boundingObject USE hinge_2_shape
              physics Physics {
              }
            }
          }
        ]
        name "solid(1)"
        boundingObject USE hinge_shape
        physics Physics {
        }
      }
    }
  ]
  boundingObject USE base_shape
  physics Physics {
  }
  controller "RRR_robot_controller"
}
